Workbook

Sheet README
B2: HELIOS CONSUMER GmbH · FP&A Sample Model
B3: Illustrative portfolio project. Prepared by Prajit Jawahar
B5: Model | C5: 06: Integrated 3-Statement Model (FY2024 to FY2027)
B6: Purpose | C6: The core FP&A build: a linked Income Statement, Balance Sheet and Cash Flow that flow from one set of drivers, roll the balance sheet forward year on year, and tie out with a balance check that must equal zero.
B7: Techniques shown | C7: Driver-based P&L · working capital from DSO / DIO / DPO days · balance-sheet roll-forward · indirect cash flow · self-balancing with a live balance check · no circular references.
B8: How to use | C8: Change any blue driver on the 'Assumptions' tab (growth, margins, working-capital days, payout). All three statements recompute and the Balance check row stays at zero.
B9: Currency / units | C9: All figures in EUR thousands (€000) unless stated.
B10: Data | C10: Sample / illustrative figures for a fictional company. Not real financials.
B12: Colour key
B13: Blue text | C13: Hard-coded input / assumption you can change
B14: Black text | C14: Formula, recalculates automatically
B15: Green text | C15: Links to another sheet
B16: Yellow fill | C16: Cells intended for you to fill in

Sheet Assumptions
B2: Model Assumptions
B3: Blue = input driver. Figures €000 unless shown as %. Days on a 365-day basis.
B5: Operating drivers
B6: Base revenue, FY2024 (€000) | C6: 45000
B7: Revenue growth, FY2025 | C7: 0.1
B8: Revenue growth, FY2026 | C8: 0.07
B9: Revenue growth, FY2027 | C9: 0.06
B10: Gross margin | C10: 0.39
B11: Operating expenses (% of revenue) | C11: 0.265
B12: Depreciation (% of opening PP&E) | C12: 0.1
B13: Capital expenditure (% of revenue) | C13: 0.03
B14: Tax rate | C14: 0.3
B15: Interest rate on debt | C15: 0.05
B16: Dividend payout (% of net income) | C16: 0.3
B17: Days sales outstanding (DSO) | C17: 45
... B19: Days payables outstanding (DPO) | C19: 52
B21: Opening balance sheet (FY2024 year-end)
B22: Cash | C22: 3000
B23: Property, plant & equipment (net) | C23: 12000
B24: Debt | C24: 6000
B25: Share capital | C25: 5000
B27: FY2024 retained earnings is derived so the opening balance sheet balances exactly.
B28: Interest is charged on opening debt (not on cash), which keeps the model free of circular references.

Sheet 3-Statement Model
B2: Helios Consumer GmbH: Integrated Financial Model
B3: EUR thousands (€000). Green = linked from Assumptions. FY2024 is the base year; FY2025 to FY2027 are forecast.
B5: €000 | C5: FY2024 | D5: FY2025 | E5: FY2026 | F5: FY2027
B6: INCOME STATEMENT
B7: Revenue | C7: =Assumptions!$C$6 | D7: =C7*(1+Assumptions!$C$7) | E7: =D7*(1+Assumptions!$C$8) | F7: =E7*(1+Assumptions!$C$9)
B8: Cost of goods sold | C8: =-C7*(1-Assumptions!$C$10) | D8: =-D7*(1-Assumptions!$C$10) | E8: =-E7*(1-Assumptions!$C$10) | F8: =-F7*(1-Assumptions!$C$10)
B9: Gross profit | C9: =C7+C8 | D9: =D7+D8 | E9: =E7+E8 | F9: =F7+F8
B10: Operating expenses | C10: =-C7*Assumptions!$C$11 | D10: =-D7*Assumptions!$C$11 | E10: =-E7*Assumptions!$C$11 | F10: =-F7*Assumptions!$C$11
B11: EBITDA | C11: =C9+C10 | D11: =D9+D10 | E11: =E9+E10 | F11: =F9+F10
B12: Depreciation & amortisation | C12: =-Assumptions!$C$12*Assumptions!$C$23 | D12: =-Assumptions!$C$12*C22 | E12: =-Assumptions!$C$12*D22 | F12: =-Assumptions!$C$12*E22
B13: EBIT | C13: =C11+C12 | D13: =D11+D12 | E13: =E11+E12 | F13: =F11+F12
B14: Interest expense | C14: =-Assumptions!$C$15*Assumptions!$C$24 | D14: =-Assumptions!$C$15*C25 | E14: =-Assumptions!$C$15*D25 | F14: =-Assumptions!$C$15*E25
B15: Profit before tax | C15: =C13+C14 | D15: =D13+D14 | E15: =E13+E14 | F15: =F13+F14
B16: Tax | C16: =-C15*Assumptions!$C$14 | D16: =-D15*Assumptions!$C$14 | E16: =-E15*Assumptions!$C$14 | F16: =-F15*Assumptions!$C$14
B17: Net income | C17: =C15+C16 | D17: =D15+D16 | E17: =E15+E16 | F17: =F15+F16
B18: BALANCE SHEET
B19: Cash | C19: =Assumptions!$C$22 | D19: =D46 | E19: =E46 | F19: =F46
B20: Accounts receivable | C20: =C7*Assumptions!$C$17/365 | D20: =D7*Assumptions!$C$17/365 | E20: =E7*Assumptions!$C$17/365 | F20: =F7*Assumptions!$C$17/365
B21: Inventory | C21: =-C8*Assumptions!$C$18/365 | D21: =-D8*Assumptions!$C$18/365 | E21: =-E8*Assumptions!$C$18/365 | F21: =-F8*Assumptions!$C$18/365
B22: Property, plant & equipment (net) | C22: =Assumptions!$C$23 | D22: =C22+D39*-1+D12 | E22: =D22+E39*-1+E12 | F22: =E22+F39*-1+F12
B23: Total assets | C23: =C19+C20+C21+C22 | D23: =D19+D20+D21+D22 | E23: =E19+E20+E21+E22 | F23: =F19+F20+F21+F22
B24: Accounts payable | C24: =-C8*Assumptions!$C$19/365 | D24: =-D8*Assumptions!$C$19/365 | E24: =-E8*Assumptions!$C$19/365 | F24: =-F8*Assumptions!$C$19/365
B25: Debt | C25: =Assumptions!$C$24 | D25: =Assumptions!$C$24 | E25: =Assumptions!$C$24 | F25: =Assumptions!$C$24
B26: Total liabilities | C26: =C24+C25 | D26: =D24+D25 | E26: =E24+E25 | F26: =F24+F25
B27: Share capital | C27: =Assumptions!$C$25 | D27: =Assumptions!$C$25 | E27: =Assumptions!$C$25 | F27: =Assumptions!$C$25
B28: Retained earnings | C28: =C23-C26-C27 | D28: =C28+D17+D41 | E28: =D28+E17+E41 | F28: =E28+F17+F41
B29: Total equity | C29: =C27+C28 | D29: =D27+D28 | E29: =E27+E28 | F29: =F27+F28
B30: Total liabilities & equity | C30: =C26+C29 | D30: =D26+D29 | E30: =E26+E29 | F30: =F26+F29
B31: Balance check (must be 0) | C31: =C23-C30 | D31: =D23-D30 | E31: =E23-E30 | F31: =F23-F30
B32: CASH FLOW (indirect)
B33: Net income | C33: n/a | D33: =D17 | E33: =E17 | F33: =F17
B34: Add back: depreciation | C34: n/a | D34: =-D12 | E34: =-E12 | F34: =-F12
B35: Change in receivables | C35: n/a | D35: =-(D20-C20) | E35: =-(E20-D20) | F35: =-(F20-E20)
B36: Change in inventory | C36: n/a | D36: =-(D21-C21) | E36: =-(E21-D21) | F36: =-(F21-E21)
B37: Change in payables | C37: n/a | D37: =D24-C24 | E37: =E24-D24 | F37: =F24-E24
B38: Cash from operations | C38: n/a | D38: =SUM(D33:D37) | E38: =SUM(E33:E37) | F38: =SUM(F33:F37)
B39: Capital expenditure | C39: n/a | D39: =-D7*Assumptions!$C$13 | E39: =-E7*Assumptions!$C$13 | F39: =-F7*Assumptions!$C$13
B40: Cash from investing | C40: n/a | D40: =D39 | E40: =E39 | F40: =F39
B41: Dividends paid | C41: n/a | D41: =-D17*Assumptions!$C$16 | E41: =-E17*Assumptions!$C$16 | F41: =-F17*Assumptions!$C$16
B42: Change in debt | C42: n/a | D42: =D25-C25 | E42: =E25-D25 | F42: =F25-E25
...
